[2025-10-02T18:12:24.349+0000] {taskinstance.py:1956} INFO - Dependencies all met for dep_context=non-requeueable deps ti=<TaskInstance: etl_pipeline_scd2.load_to_dw_scd2 manual__2025-10-02T18:10:31.973688+00:00 [queued]>
[2025-10-02T18:12:24.363+0000] {taskinstance.py:1956} INFO - Dependencies all met for dep_context=requeueable deps ti=<TaskInstance: etl_pipeline_scd2.load_to_dw_scd2 manual__2025-10-02T18:10:31.973688+00:00 [queued]>
[2025-10-02T18:12:24.365+0000] {taskinstance.py:2170} INFO - Starting attempt 1 of 1
[2025-10-02T18:12:24.402+0000] {taskinstance.py:2191} INFO - Executing <Task(PythonOperator): load_to_dw_scd2> on 2025-10-02 18:10:31.973688+00:00
[2025-10-02T18:12:24.412+0000] {standard_task_runner.py:60} INFO - Started process 1695 to run task
[2025-10-02T18:12:24.419+0000] {standard_task_runner.py:87} INFO - Running: ['***', 'tasks', 'run', 'etl_pipeline_scd2', 'load_to_dw_scd2', 'manual__2025-10-02T18:10:31.973688+00:00', '--job-id', '74', '--raw', '--subdir', 'DAGS_FOLDER/process_scripts.py', '--cfg-path', '/tmp/tmpozq5_g2g']
[2025-10-02T18:12:24.423+0000] {standard_task_runner.py:88} INFO - Job 74: Subtask load_to_dw_scd2
[2025-10-02T18:12:24.479+0000] {logging_mixin.py:188} WARNING - /home/***/.local/lib/python3.11/site-packages/***/settings.py:194 DeprecationWarning: The sql_alchemy_conn option in [core] has been moved to the sql_alchemy_conn option in [database] - the old setting has been used, but please update your config.
[2025-10-02T18:12:24.555+0000] {task_command.py:423} INFO - Running <TaskInstance: etl_pipeline_scd2.load_to_dw_scd2 manual__2025-10-02T18:10:31.973688+00:00 [running]> on host f327b3c387fa
[2025-10-02T18:12:24.670+0000] {taskinstance.py:2480} INFO - Exporting env vars: AIRFLOW_CTX_DAG_OWNER='***' AIRFLOW_CTX_DAG_ID='etl_pipeline_scd2' AIRFLOW_CTX_TASK_ID='load_to_dw_scd2' AIRFLOW_CTX_EXECUTION_DATE='2025-10-02T18:10:31.973688+00:00' AIRFLOW_CTX_TRY_NUMBER='1' AIRFLOW_CTX_DAG_RUN_ID='manual__2025-10-02T18:10:31.973688+00:00'
[2025-10-02T18:12:25.967+0000] {scd2_loader.py:196} INFO - Processing file: Country_code.xlsx
[2025-10-02T18:12:28.610+0000] {scd2_loader.py:241} WARNING - 1 lignes ignor√©es dans Country_code.xlsx::0 (business_keys manquantes)
[2025-10-02T18:12:28.729+0000] {scd2_loader.py:138} ERROR - Erreur lecture existants pour dim_pays: (MySQLdb.ProgrammingError) (1064, "You have an error in your SQL syntax; check the manual that corresponds to your MySQL server version for the right syntax to use near ':country_code_0) OR (`country_code` = :country_code_1) OR (`country_code` = :cou' at line 1")
[SQL: SELECT * FROM `dim_pays` WHERE is_current=1 AND ((`country_code` = :country_code_0) OR (`country_code` = :country_code_1) OR (`country_code` = :country_code_2) OR (`country_code` = :country_code_3) OR (`country_code` = :country_code_4) OR (`country_code` = :country_code_5) OR (`country_code` = :country_code_6) OR (`country_code` = :country_code_7) OR (`country_code` = :country_code_8) OR (`country_code` = :country_code_9) OR (`country_code` = :country_code_10) OR (`country_code` = :country_code_11) OR (`country_code` = :country_code_12) OR (`country_code` = :country_code_13) OR (`country_code` = :country_code_14) OR (`country_code` = :country_code_15) OR (`country_code` = :country_code_16) OR (`country_code` = :country_code_17) OR (`country_code` = :country_code_18) OR (`country_code` = :country_code_19) OR (`country_code` = :country_code_20) OR (`country_code` = :country_code_21) OR (`country_code` = :country_code_22) OR (`country_code` = :country_code_23) OR (`country_code` = :country_code_24) OR (`country_code` = :country_code_25) OR (`country_code` = :country_code_26) OR (`country_code` = :country_code_27) OR (`country_code` = :country_code_28))]
[parameters: {'country_code_0': 'NG', 'country_code_1': 'YT', 'country_code_2': 'ER', 'country_code_3': 'ET', 'country_code_4': 'MG', 'country_code_5': 'MA', 'country_code_6': 'MU', 'country_code_7': 'RE', 'country_code_8': 'TN', 'country_code_9': 'TG', 'country_code_10': 'TD', 'country_code_11': 'SN', 'country_code_12': 'ML', 'country_code_13': 'GH', 'country_code_14': 'GN', 'country_code_15': 'BW', 'country_code_16': 'ZA', 'country_code_17': 'SZ', 'country_code_18': 'MW', 'country_code_19': 'AO', 'country_code_20': 'MZ', 'country_code_21': 'ZW', 'country_code_22': 'ZM', 'country_code_23': 'CM', 'country_code_24': 'CD', 'country_code_25': 'GA', 'country_code_26': 'KE', 'country_code_27': 'UG', 'country_code_28': 'TZ'}]
(Background on this error at: https://sqlalche.me/e/14/f405)
Traceback (most recent call last):
  File "/home/airflow/.local/lib/python3.11/site-packages/sqlalchemy/engine/base.py", line 1910, in _execute_context
    self.dialect.do_execute(
  File "/home/airflow/.local/lib/python3.11/site-packages/sqlalchemy/engine/default.py", line 736, in do_execute
    cursor.execute(statement, parameters)
  File "/home/airflow/.local/lib/python3.11/site-packages/MySQLdb/cursors.py", line 179, in execute
    res = self._query(mogrified_query)
          ^^^^^^^^^^^^^^^^^^^^^^^^^^^^
  File "/home/airflow/.local/lib/python3.11/site-packages/MySQLdb/cursors.py", line 330, in _query
    db.query(q)
  File "/home/airflow/.local/lib/python3.11/site-packages/MySQLdb/connections.py", line 257, in query
    _mysql.connection.query(self, query)
MySQLdb.ProgrammingError: (1064, "You have an error in your SQL syntax; check the manual that corresponds to your MySQL server version for the right syntax to use near ':country_code_0) OR (`country_code` = :country_code_1) OR (`country_code` = :cou' at line 1")

The above exception was the direct cause of the following exception:

Traceback (most recent call last):
  File "/opt/airflow/dags/scd2_loader.py", line 132, in _process_table_batch
    existing_df = pd.read_sql(select_sql, engine, params=params)
                  ^^^^^^^^^^^^^^^^^^^^^^^^^^^^^^^^^^^^^^^^^^^^^^
  File "/home/airflow/.local/lib/python3.11/site-packages/pandas/io/sql.py", line 682, in read_sql
    return pandas_sql.read_query(
           ^^^^^^^^^^^^^^^^^^^^^^
  File "/home/airflow/.local/lib/python3.11/site-packages/pandas/io/sql.py", line 1776, in read_query
    result = self.execute(sql, params)
             ^^^^^^^^^^^^^^^^^^^^^^^^^
  File "/home/airflow/.local/lib/python3.11/site-packages/pandas/io/sql.py", line 1599, in execute
    return self.con.exec_driver_sql(sql, *args)
           ^^^^^^^^^^^^^^^^^^^^^^^^^^^^^^^^^^^^
  File "/home/airflow/.local/lib/python3.11/site-packages/sqlalchemy/engine/base.py", line 1770, in exec_driver_sql
    return self._exec_driver_sql(
           ^^^^^^^^^^^^^^^^^^^^^^
  File "/home/airflow/.local/lib/python3.11/site-packages/sqlalchemy/engine/base.py", line 1674, in _exec_driver_sql
    ret = self._execute_context(
          ^^^^^^^^^^^^^^^^^^^^^^
  File "/home/airflow/.local/lib/python3.11/site-packages/sqlalchemy/engine/base.py", line 1953, in _execute_context
    self._handle_dbapi_exception(
  File "/home/airflow/.local/lib/python3.11/site-packages/sqlalchemy/engine/base.py", line 2134, in _handle_dbapi_exception
    util.raise_(
  File "/home/airflow/.local/lib/python3.11/site-packages/sqlalchemy/util/compat.py", line 211, in raise_
    raise exception
  File "/home/airflow/.local/lib/python3.11/site-packages/sqlalchemy/engine/base.py", line 1910, in _execute_context
    self.dialect.do_execute(
  File "/home/airflow/.local/lib/python3.11/site-packages/sqlalchemy/engine/default.py", line 736, in do_execute
    cursor.execute(statement, parameters)
  File "/home/airflow/.local/lib/python3.11/site-packages/MySQLdb/cursors.py", line 179, in execute
    res = self._query(mogrified_query)
          ^^^^^^^^^^^^^^^^^^^^^^^^^^^^
  File "/home/airflow/.local/lib/python3.11/site-packages/MySQLdb/cursors.py", line 330, in _query
    db.query(q)
  File "/home/airflow/.local/lib/python3.11/site-packages/MySQLdb/connections.py", line 257, in query
    _mysql.connection.query(self, query)
sqlalchemy.exc.ProgrammingError: (MySQLdb.ProgrammingError) (1064, "You have an error in your SQL syntax; check the manual that corresponds to your MySQL server version for the right syntax to use near ':country_code_0) OR (`country_code` = :country_code_1) OR (`country_code` = :cou' at line 1")
[SQL: SELECT * FROM `dim_pays` WHERE is_current=1 AND ((`country_code` = :country_code_0) OR (`country_code` = :country_code_1) OR (`country_code` = :country_code_2) OR (`country_code` = :country_code_3) OR (`country_code` = :country_code_4) OR (`country_code` = :country_code_5) OR (`country_code` = :country_code_6) OR (`country_code` = :country_code_7) OR (`country_code` = :country_code_8) OR (`country_code` = :country_code_9) OR (`country_code` = :country_code_10) OR (`country_code` = :country_code_11) OR (`country_code` = :country_code_12) OR (`country_code` = :country_code_13) OR (`country_code` = :country_code_14) OR (`country_code` = :country_code_15) OR (`country_code` = :country_code_16) OR (`country_code` = :country_code_17) OR (`country_code` = :country_code_18) OR (`country_code` = :country_code_19) OR (`country_code` = :country_code_20) OR (`country_code` = :country_code_21) OR (`country_code` = :country_code_22) OR (`country_code` = :country_code_23) OR (`country_code` = :country_code_24) OR (`country_code` = :country_code_25) OR (`country_code` = :country_code_26) OR (`country_code` = :country_code_27) OR (`country_code` = :country_code_28))]
[parameters: {'country_code_0': 'NG', 'country_code_1': 'YT', 'country_code_2': 'ER', 'country_code_3': 'ET', 'country_code_4': 'MG', 'country_code_5': 'MA', 'country_code_6': 'MU', 'country_code_7': 'RE', 'country_code_8': 'TN', 'country_code_9': 'TG', 'country_code_10': 'TD', 'country_code_11': 'SN', 'country_code_12': 'ML', 'country_code_13': 'GH', 'country_code_14': 'GN', 'country_code_15': 'BW', 'country_code_16': 'ZA', 'country_code_17': 'SZ', 'country_code_18': 'MW', 'country_code_19': 'AO', 'country_code_20': 'MZ', 'country_code_21': 'ZW', 'country_code_22': 'ZM', 'country_code_23': 'CM', 'country_code_24': 'CD', 'country_code_25': 'GA', 'country_code_26': 'KE', 'country_code_27': 'UG', 'country_code_28': 'TZ'}]
(Background on this error at: https://sqlalche.me/e/14/f405)
[2025-10-02T18:12:28.848+0000] {taskinstance.py:2698} ERROR - Task failed with exception
Traceback (most recent call last):
  File "/home/airflow/.local/lib/python3.11/site-packages/sqlalchemy/engine/base.py", line 1890, in _execute_context
    self.dialect.do_executemany(
  File "/home/airflow/.local/lib/python3.11/site-packages/sqlalchemy/dialects/mysql/mysqldb.py", line 183, in do_executemany
    rowcount = cursor.executemany(statement, parameters)
               ^^^^^^^^^^^^^^^^^^^^^^^^^^^^^^^^^^^^^^^^^
  File "/home/airflow/.local/lib/python3.11/site-packages/MySQLdb/cursors.py", line 241, in executemany
    return self._do_execute_many(
           ^^^^^^^^^^^^^^^^^^^^^^
  File "/home/airflow/.local/lib/python3.11/site-packages/MySQLdb/cursors.py", line 275, in _do_execute_many
    rows += self.execute(sql + postfix)
            ^^^^^^^^^^^^^^^^^^^^^^^^^^^
  File "/home/airflow/.local/lib/python3.11/site-packages/MySQLdb/cursors.py", line 179, in execute
    res = self._query(mogrified_query)
          ^^^^^^^^^^^^^^^^^^^^^^^^^^^^
  File "/home/airflow/.local/lib/python3.11/site-packages/MySQLdb/cursors.py", line 330, in _query
    db.query(q)
  File "/home/airflow/.local/lib/python3.11/site-packages/MySQLdb/connections.py", line 257, in query
    _mysql.connection.query(self, query)
MySQLdb.IntegrityError: (1062, "Duplicate entry 'NG' for key 'dim_pays.uniq_business'")

The above exception was the direct cause of the following exception:

Traceback (most recent call last):
  File "/home/airflow/.local/lib/python3.11/site-packages/airflow/models/taskinstance.py", line 433, in _execute_task
    result = execute_callable(context=context, **execute_callable_kwargs)
             ^^^^^^^^^^^^^^^^^^^^^^^^^^^^^^^^^^^^^^^^^^^^^^^^^^^^^^^^^^^^
  File "/home/airflow/.local/lib/python3.11/site-packages/airflow/operators/python.py", line 199, in execute
    return_value = self.execute_callable()
                   ^^^^^^^^^^^^^^^^^^^^^^^
  File "/home/airflow/.local/lib/python3.11/site-packages/airflow/operators/python.py", line 216, in execute_callable
    return self.python_callable(*self.op_args, **self.op_kwargs)
           ^^^^^^^^^^^^^^^^^^^^^^^^^^^^^^^^^^^^^^^^^^^^^^^^^^^^^
  File "/opt/airflow/dags/process_scripts.py", line 28, in run_scd2_loader
    load_all_out_files_to_dw()
  File "/opt/airflow/dags/scd2_loader.py", line 243, in load_all_out_files_to_dw
    ins, upd = _process_table_batch(engine, table_name, df, business_keys, now)
               ^^^^^^^^^^^^^^^^^^^^^^^^^^^^^^^^^^^^^^^^^^^^^^^^^^^^^^^^^^^^^^^^
  File "/opt/airflow/dags/scd2_loader.py", line 175, in _process_table_batch
    conn.execute(insert_sql_text, chunk)
  File "/home/airflow/.local/lib/python3.11/site-packages/sqlalchemy/engine/base.py", line 1385, in execute
    return meth(self, multiparams, params, _EMPTY_EXECUTION_OPTS)
           ^^^^^^^^^^^^^^^^^^^^^^^^^^^^^^^^^^^^^^^^^^^^^^^^^^^^^^
  File "/home/airflow/.local/lib/python3.11/site-packages/sqlalchemy/sql/elements.py", line 334, in _execute_on_connection
    return connection._execute_clauseelement(
           ^^^^^^^^^^^^^^^^^^^^^^^^^^^^^^^^^^
  File "/home/airflow/.local/lib/python3.11/site-packages/sqlalchemy/engine/base.py", line 1577, in _execute_clauseelement
    ret = self._execute_context(
          ^^^^^^^^^^^^^^^^^^^^^^
  File "/home/airflow/.local/lib/python3.11/site-packages/sqlalchemy/engine/base.py", line 1953, in _execute_context
    self._handle_dbapi_exception(
  File "/home/airflow/.local/lib/python3.11/site-packages/sqlalchemy/engine/base.py", line 2134, in _handle_dbapi_exception
    util.raise_(
  File "/home/airflow/.local/lib/python3.11/site-packages/sqlalchemy/util/compat.py", line 211, in raise_
    raise exception
  File "/home/airflow/.local/lib/python3.11/site-packages/sqlalchemy/engine/base.py", line 1890, in _execute_context
    self.dialect.do_executemany(
  File "/home/airflow/.local/lib/python3.11/site-packages/sqlalchemy/dialects/mysql/mysqldb.py", line 183, in do_executemany
    rowcount = cursor.executemany(statement, parameters)
               ^^^^^^^^^^^^^^^^^^^^^^^^^^^^^^^^^^^^^^^^^
  File "/home/airflow/.local/lib/python3.11/site-packages/MySQLdb/cursors.py", line 241, in executemany
    return self._do_execute_many(
           ^^^^^^^^^^^^^^^^^^^^^^
  File "/home/airflow/.local/lib/python3.11/site-packages/MySQLdb/cursors.py", line 275, in _do_execute_many
    rows += self.execute(sql + postfix)
            ^^^^^^^^^^^^^^^^^^^^^^^^^^^
  File "/home/airflow/.local/lib/python3.11/site-packages/MySQLdb/cursors.py", line 179, in execute
    res = self._query(mogrified_query)
          ^^^^^^^^^^^^^^^^^^^^^^^^^^^^
  File "/home/airflow/.local/lib/python3.11/site-packages/MySQLdb/cursors.py", line 330, in _query
    db.query(q)
  File "/home/airflow/.local/lib/python3.11/site-packages/MySQLdb/connections.py", line 257, in query
    _mysql.connection.query(self, query)
sqlalchemy.exc.IntegrityError: (MySQLdb.IntegrityError) (1062, "Duplicate entry 'NG' for key 'dim_pays.uniq_business'")
[SQL: INSERT INTO `dim_pays` (`country_code`, `country`, `is_current`, `start_date`) VALUES (%s, %s, %s, %s)]
[parameters: (('NG', 'Nig√©ria', 1, datetime.datetime(2025, 10, 2, 18, 12, 25, 950325, tzinfo=datetime.timezone.utc)), ('YT', 'Mayotte', 1, datetime.datetime(2025, 10, 2, 18, 12, 25, 950325, tzinfo=datetime.timezone.utc)), ('ER', 'Erythr√©e', 1, datetime.datetime(2025, 10, 2, 18, 12, 25, 950325, tzinfo=datetime.timezone.utc)), ('ET', 'Ethiopie', 1, datetime.datetime(2025, 10, 2, 18, 12, 25, 950325, tzinfo=datetime.timezone.utc)), ('MG', 'Madagascar', 1, datetime.datetime(2025, 10, 2, 18, 12, 25, 950325, tzinfo=datetime.timezone.utc)), ('MA', 'Maroc', 1, datetime.datetime(2025, 10, 2, 18, 12, 25, 950325, tzinfo=datetime.timezone.utc)), ('MU', 'Maurice', 1, datetime.datetime(2025, 10, 2, 18, 12, 25, 950325, tzinfo=datetime.timezone.utc)), ('RE', 'R√©union', 1, datetime.datetime(2025, 10, 2, 18, 12, 25, 950325, tzinfo=datetime.timezone.utc))  ... displaying 10 of 29 total bound parameter sets ...  ('UG', 'Uganda', 1, datetime.datetime(2025, 10, 2, 18, 12, 25, 950325, tzinfo=datetime.timezone.utc)), ('TZ', 'Tanzania', 1, datetime.datetime(2025, 10, 2, 18, 12, 25, 950325, tzinfo=datetime.timezone.utc)))]
(Background on this error at: https://sqlalche.me/e/14/gkpj)
[2025-10-02T18:12:28.991+0000] {taskinstance.py:1138} INFO - Marking task as FAILED. dag_id=etl_pipeline_scd2, task_id=load_to_dw_scd2, execution_date=20251002T181031, start_date=20251002T181224, end_date=20251002T181228
[2025-10-02T18:12:29.039+0000] {standard_task_runner.py:107} ERROR - Failed to execute job 74 for task load_to_dw_scd2 ((MySQLdb.IntegrityError) (1062, "Duplicate entry 'NG' for key 'dim_pays.uniq_business'")
[SQL: INSERT INTO `dim_pays` (`country_code`, `country`, `is_current`, `start_date`) VALUES (%s, %s, %s, %s)]
[parameters: (('NG', 'Nig√©ria', 1, datetime.datetime(2025, 10, 2, 18, 12, 25, 950325, tzinfo=datetime.timezone.utc)), ('YT', 'Mayotte', 1, datetime.datetime(2025, 10, 2, 18, 12, 25, 950325, tzinfo=datetime.timezone.utc)), ('ER', 'Erythr√©e', 1, datetime.datetime(2025, 10, 2, 18, 12, 25, 950325, tzinfo=datetime.timezone.utc)), ('ET', 'Ethiopie', 1, datetime.datetime(2025, 10, 2, 18, 12, 25, 950325, tzinfo=datetime.timezone.utc)), ('MG', 'Madagascar', 1, datetime.datetime(2025, 10, 2, 18, 12, 25, 950325, tzinfo=datetime.timezone.utc)), ('MA', 'Maroc', 1, datetime.datetime(2025, 10, 2, 18, 12, 25, 950325, tzinfo=datetime.timezone.utc)), ('MU', 'Maurice', 1, datetime.datetime(2025, 10, 2, 18, 12, 25, 950325, tzinfo=datetime.timezone.utc)), ('RE', 'R√©union', 1, datetime.datetime(2025, 10, 2, 18, 12, 25, 950325, tzinfo=datetime.timezone.utc))  ... displaying 10 of 29 total bound parameter sets ...  ('UG', 'Uganda', 1, datetime.datetime(2025, 10, 2, 18, 12, 25, 950325, tzinfo=datetime.timezone.utc)), ('TZ', 'Tanzania', 1, datetime.datetime(2025, 10, 2, 18, 12, 25, 950325, tzinfo=datetime.timezone.utc)))]
(Background on this error at: https://sqlalche.me/e/14/gkpj); 1695)
[2025-10-02T18:12:29.101+0000] {local_task_job_runner.py:234} INFO - Task exited with return code 1
[2025-10-02T18:12:29.133+0000] {taskinstance.py:3280} INFO - 0 downstream tasks scheduled from follow-on schedule check
