[2025-10-02T16:24:53.759+0000] {taskinstance.py:1956} INFO - Dependencies all met for dep_context=non-requeueable deps ti=<TaskInstance: etl_pipeline_scd2.load_to_dw_scd2 manual__2025-10-02T16:22:56.072689+00:00 [queued]>
[2025-10-02T16:24:53.819+0000] {taskinstance.py:1956} INFO - Dependencies all met for dep_context=requeueable deps ti=<TaskInstance: etl_pipeline_scd2.load_to_dw_scd2 manual__2025-10-02T16:22:56.072689+00:00 [queued]>
[2025-10-02T16:24:53.827+0000] {taskinstance.py:2170} INFO - Starting attempt 1 of 1
[2025-10-02T16:24:53.893+0000] {taskinstance.py:2191} INFO - Executing <Task(PythonOperator): load_to_dw_scd2> on 2025-10-02 16:22:56.072689+00:00
[2025-10-02T16:24:53.929+0000] {standard_task_runner.py:60} INFO - Started process 421 to run task
[2025-10-02T16:24:53.948+0000] {standard_task_runner.py:87} INFO - Running: ['***', 'tasks', 'run', 'etl_pipeline_scd2', 'load_to_dw_scd2', 'manual__2025-10-02T16:22:56.072689+00:00', '--job-id', '54', '--raw', '--subdir', 'DAGS_FOLDER/process_scripts.py', '--cfg-path', '/tmp/tmphe3ili8v']
[2025-10-02T16:24:53.986+0000] {standard_task_runner.py:88} INFO - Job 54: Subtask load_to_dw_scd2
[2025-10-02T16:24:54.053+0000] {logging_mixin.py:188} WARNING - /home/***/.local/lib/python3.11/site-packages/***/settings.py:194 DeprecationWarning: The sql_alchemy_conn option in [core] has been moved to the sql_alchemy_conn option in [database] - the old setting has been used, but please update your config.
[2025-10-02T16:24:54.258+0000] {task_command.py:423} INFO - Running <TaskInstance: etl_pipeline_scd2.load_to_dw_scd2 manual__2025-10-02T16:22:56.072689+00:00 [running]> on host f327b3c387fa
[2025-10-02T16:24:54.482+0000] {taskinstance.py:2480} INFO - Exporting env vars: AIRFLOW_CTX_DAG_OWNER='***' AIRFLOW_CTX_DAG_ID='etl_pipeline_scd2' AIRFLOW_CTX_TASK_ID='load_to_dw_scd2' AIRFLOW_CTX_EXECUTION_DATE='2025-10-02T16:22:56.072689+00:00' AIRFLOW_CTX_TRY_NUMBER='1' AIRFLOW_CTX_DAG_RUN_ID='manual__2025-10-02T16:22:56.072689+00:00'
[2025-10-02T16:24:59.621+0000] {scd2_loader.py:78} INFO - Table `dim_pays` créée avec clés uniques: `country_code`
[2025-10-02T16:24:59.642+0000] {scd2_loader.py:154} INFO - [INSERT] Nouvelle ligne ajoutée dans `dim_pays` ({'country_code': 'NG'})
[2025-10-02T16:24:59.645+0000] {scd2_loader.py:154} INFO - [INSERT] Nouvelle ligne ajoutée dans `dim_pays` ({'country_code': 'YT'})
[2025-10-02T16:24:59.649+0000] {scd2_loader.py:154} INFO - [INSERT] Nouvelle ligne ajoutée dans `dim_pays` ({'country_code': 'ER'})
[2025-10-02T16:24:59.653+0000] {scd2_loader.py:154} INFO - [INSERT] Nouvelle ligne ajoutée dans `dim_pays` ({'country_code': 'ET'})
[2025-10-02T16:24:59.656+0000] {scd2_loader.py:154} INFO - [INSERT] Nouvelle ligne ajoutée dans `dim_pays` ({'country_code': 'MG'})
[2025-10-02T16:24:59.660+0000] {scd2_loader.py:154} INFO - [INSERT] Nouvelle ligne ajoutée dans `dim_pays` ({'country_code': 'MA'})
[2025-10-02T16:24:59.662+0000] {scd2_loader.py:154} INFO - [INSERT] Nouvelle ligne ajoutée dans `dim_pays` ({'country_code': 'MU'})
[2025-10-02T16:24:59.666+0000] {scd2_loader.py:154} INFO - [INSERT] Nouvelle ligne ajoutée dans `dim_pays` ({'country_code': 'RE'})
[2025-10-02T16:24:59.671+0000] {scd2_loader.py:154} INFO - [INSERT] Nouvelle ligne ajoutée dans `dim_pays` ({'country_code': 'TN'})
[2025-10-02T16:24:59.677+0000] {scd2_loader.py:154} INFO - [INSERT] Nouvelle ligne ajoutée dans `dim_pays` ({'country_code': 'TG'})
[2025-10-02T16:24:59.683+0000] {scd2_loader.py:154} INFO - [INSERT] Nouvelle ligne ajoutée dans `dim_pays` ({'country_code': 'TD'})
[2025-10-02T16:24:59.688+0000] {scd2_loader.py:154} INFO - [INSERT] Nouvelle ligne ajoutée dans `dim_pays` ({'country_code': 'SN'})
[2025-10-02T16:24:59.691+0000] {scd2_loader.py:154} INFO - [INSERT] Nouvelle ligne ajoutée dans `dim_pays` ({'country_code': 'ML'})
[2025-10-02T16:24:59.695+0000] {scd2_loader.py:154} INFO - [INSERT] Nouvelle ligne ajoutée dans `dim_pays` ({'country_code': 'GH'})
[2025-10-02T16:24:59.700+0000] {scd2_loader.py:154} INFO - [INSERT] Nouvelle ligne ajoutée dans `dim_pays` ({'country_code': 'GN'})
[2025-10-02T16:24:59.705+0000] {scd2_loader.py:154} INFO - [INSERT] Nouvelle ligne ajoutée dans `dim_pays` ({'country_code': 'BW'})
[2025-10-02T16:24:59.707+0000] {scd2_loader.py:154} INFO - [INSERT] Nouvelle ligne ajoutée dans `dim_pays` ({'country_code': 'ZA'})
[2025-10-02T16:24:59.709+0000] {scd2_loader.py:154} INFO - [INSERT] Nouvelle ligne ajoutée dans `dim_pays` ({'country_code': 'SZ'})
[2025-10-02T16:24:59.711+0000] {scd2_loader.py:154} INFO - [INSERT] Nouvelle ligne ajoutée dans `dim_pays` ({'country_code': 'MW'})
[2025-10-02T16:24:59.713+0000] {scd2_loader.py:154} INFO - [INSERT] Nouvelle ligne ajoutée dans `dim_pays` ({'country_code': 'AO'})
[2025-10-02T16:24:59.715+0000] {scd2_loader.py:154} INFO - [INSERT] Nouvelle ligne ajoutée dans `dim_pays` ({'country_code': 'MZ'})
[2025-10-02T16:24:59.734+0000] {taskinstance.py:2698} ERROR - Task failed with exception
Traceback (most recent call last):
  File "/home/airflow/.local/lib/python3.11/site-packages/sqlalchemy/engine/base.py", line 1910, in _execute_context
    self.dialect.do_execute(
  File "/home/airflow/.local/lib/python3.11/site-packages/sqlalchemy/engine/default.py", line 736, in do_execute
    cursor.execute(statement, parameters)
  File "/home/airflow/.local/lib/python3.11/site-packages/MySQLdb/cursors.py", line 176, in execute
    mogrified_query = self._mogrify(query, args)
                      ^^^^^^^^^^^^^^^^^^^^^^^^^^
  File "/home/airflow/.local/lib/python3.11/site-packages/MySQLdb/cursors.py", line 198, in _mogrify
    args = tuple(map(db.literal, args))
           ^^^^^^^^^^^^^^^^^^^^^^^^^^^^
  File "/home/airflow/.local/lib/python3.11/site-packages/MySQLdb/connections.py", line 286, in literal
    s = self.escape(o, self.encoders)
        ^^^^^^^^^^^^^^^^^^^^^^^^^^^^^
  File "/home/airflow/.local/lib/python3.11/site-packages/MySQLdb/converters.py", line 76, in Float2Str
    raise ProgrammingError("%s can not be used with MySQL" % s)
MySQLdb.ProgrammingError: nan can not be used with MySQL

The above exception was the direct cause of the following exception:

Traceback (most recent call last):
  File "/home/airflow/.local/lib/python3.11/site-packages/airflow/models/taskinstance.py", line 433, in _execute_task
    result = execute_callable(context=context, **execute_callable_kwargs)
             ^^^^^^^^^^^^^^^^^^^^^^^^^^^^^^^^^^^^^^^^^^^^^^^^^^^^^^^^^^^^
  File "/home/airflow/.local/lib/python3.11/site-packages/airflow/operators/python.py", line 199, in execute
    return_value = self.execute_callable()
                   ^^^^^^^^^^^^^^^^^^^^^^^
  File "/home/airflow/.local/lib/python3.11/site-packages/airflow/operators/python.py", line 216, in execute_callable
    return self.python_callable(*self.op_args, **self.op_kwargs)
           ^^^^^^^^^^^^^^^^^^^^^^^^^^^^^^^^^^^^^^^^^^^^^^^^^^^^^
  File "/opt/airflow/dags/process_scripts.py", line 28, in run_scd2_loader
    load_all_out_files_to_dw()
  File "/opt/airflow/dags/scd2_loader.py", line 141, in load_all_out_files_to_dw
    existing = conn.execute(select_sql, params).mappings().first()
               ^^^^^^^^^^^^^^^^^^^^^^^^^^^^^^^^
  File "/home/airflow/.local/lib/python3.11/site-packages/sqlalchemy/engine/base.py", line 1385, in execute
    return meth(self, multiparams, params, _EMPTY_EXECUTION_OPTS)
           ^^^^^^^^^^^^^^^^^^^^^^^^^^^^^^^^^^^^^^^^^^^^^^^^^^^^^^
  File "/home/airflow/.local/lib/python3.11/site-packages/sqlalchemy/sql/elements.py", line 334, in _execute_on_connection
    return connection._execute_clauseelement(
           ^^^^^^^^^^^^^^^^^^^^^^^^^^^^^^^^^^
  File "/home/airflow/.local/lib/python3.11/site-packages/sqlalchemy/engine/base.py", line 1577, in _execute_clauseelement
    ret = self._execute_context(
          ^^^^^^^^^^^^^^^^^^^^^^
  File "/home/airflow/.local/lib/python3.11/site-packages/sqlalchemy/engine/base.py", line 1953, in _execute_context
    self._handle_dbapi_exception(
  File "/home/airflow/.local/lib/python3.11/site-packages/sqlalchemy/engine/base.py", line 2134, in _handle_dbapi_exception
    util.raise_(
  File "/home/airflow/.local/lib/python3.11/site-packages/sqlalchemy/util/compat.py", line 211, in raise_
    raise exception
  File "/home/airflow/.local/lib/python3.11/site-packages/sqlalchemy/engine/base.py", line 1910, in _execute_context
    self.dialect.do_execute(
  File "/home/airflow/.local/lib/python3.11/site-packages/sqlalchemy/engine/default.py", line 736, in do_execute
    cursor.execute(statement, parameters)
  File "/home/airflow/.local/lib/python3.11/site-packages/MySQLdb/cursors.py", line 176, in execute
    mogrified_query = self._mogrify(query, args)
                      ^^^^^^^^^^^^^^^^^^^^^^^^^^
  File "/home/airflow/.local/lib/python3.11/site-packages/MySQLdb/cursors.py", line 198, in _mogrify
    args = tuple(map(db.literal, args))
           ^^^^^^^^^^^^^^^^^^^^^^^^^^^^
  File "/home/airflow/.local/lib/python3.11/site-packages/MySQLdb/connections.py", line 286, in literal
    s = self.escape(o, self.encoders)
        ^^^^^^^^^^^^^^^^^^^^^^^^^^^^^
  File "/home/airflow/.local/lib/python3.11/site-packages/MySQLdb/converters.py", line 76, in Float2Str
    raise ProgrammingError("%s can not be used with MySQL" % s)
sqlalchemy.exc.ProgrammingError: (MySQLdb.ProgrammingError) nan can not be used with MySQL
[SQL: SELECT * FROM `dim_pays` WHERE `country_code` = %s AND is_current=1]
[parameters: (nan,)]
(Background on this error at: https://sqlalche.me/e/14/f405)
[2025-10-02T16:24:59.838+0000] {taskinstance.py:1138} INFO - Marking task as FAILED. dag_id=etl_pipeline_scd2, task_id=load_to_dw_scd2, execution_date=20251002T162256, start_date=20251002T162453, end_date=20251002T162459
[2025-10-02T16:24:59.894+0000] {standard_task_runner.py:107} ERROR - Failed to execute job 54 for task load_to_dw_scd2 ((MySQLdb.ProgrammingError) nan can not be used with MySQL
[SQL: SELECT * FROM `dim_pays` WHERE `country_code` = %s AND is_current=1]
[parameters: (nan,)]
(Background on this error at: https://sqlalche.me/e/14/f405); 421)
[2025-10-02T16:24:59.964+0000] {local_task_job_runner.py:234} INFO - Task exited with return code 1
[2025-10-02T16:24:59.985+0000] {taskinstance.py:3280} INFO - 0 downstream tasks scheduled from follow-on schedule check
