[2025-09-27T17:56:35.641+0000] {taskinstance.py:1956} INFO - Dependencies all met for dep_context=non-requeueable deps ti=<TaskInstance: dynamic_process_scripts_dag.run_processor_extract_country manual__2025-09-27T17:56:29.017669+00:00 [queued]>
[2025-09-27T17:56:35.667+0000] {taskinstance.py:1956} INFO - Dependencies all met for dep_context=requeueable deps ti=<TaskInstance: dynamic_process_scripts_dag.run_processor_extract_country manual__2025-09-27T17:56:29.017669+00:00 [queued]>
[2025-09-27T17:56:35.669+0000] {taskinstance.py:2170} INFO - Starting attempt 1 of 1
[2025-09-27T17:56:35.716+0000] {taskinstance.py:2191} INFO - Executing <Task(PythonOperator): run_processor_extract_country> on 2025-09-27 17:56:29.017669+00:00
[2025-09-27T17:56:35.752+0000] {standard_task_runner.py:60} INFO - Started process 254 to run task
[2025-09-27T17:56:35.761+0000] {standard_task_runner.py:87} INFO - Running: ['***', 'tasks', 'run', 'dynamic_process_scripts_dag', 'run_processor_extract_country', 'manual__2025-09-27T17:56:29.017669+00:00', '--job-id', '8', '--raw', '--subdir', 'DAGS_FOLDER/process_scripts.py', '--cfg-path', '/tmp/tmpmc_7bv4s']
[2025-09-27T17:56:35.768+0000] {standard_task_runner.py:88} INFO - Job 8: Subtask run_processor_extract_country
[2025-09-27T17:56:35.819+0000] {logging_mixin.py:188} WARNING - /home/***/.local/lib/python3.11/site-packages/***/settings.py:194 DeprecationWarning: The sql_alchemy_conn option in [core] has been moved to the sql_alchemy_conn option in [database] - the old setting has been used, but please update your config.
[2025-09-27T17:56:35.954+0000] {task_command.py:423} INFO - Running <TaskInstance: dynamic_process_scripts_dag.run_processor_extract_country manual__2025-09-27T17:56:29.017669+00:00 [running]> on host d6cf4dd08993
[2025-09-27T17:56:36.193+0000] {taskinstance.py:2480} INFO - Exporting env vars: AIRFLOW_CTX_DAG_OWNER='***' AIRFLOW_CTX_DAG_ID='dynamic_process_scripts_dag' AIRFLOW_CTX_TASK_ID='run_processor_extract_country' AIRFLOW_CTX_EXECUTION_DATE='2025-09-27T17:56:29.017669+00:00' AIRFLOW_CTX_TRY_NUMBER='1' AIRFLOW_CTX_DAG_RUN_ID='manual__2025-09-27T17:56:29.017669+00:00'
[2025-09-27T17:56:39.638+0000] {taskinstance.py:2698} ERROR - Task failed with exception
Traceback (most recent call last):
  File "/home/airflow/.local/lib/python3.11/site-packages/airflow/models/taskinstance.py", line 433, in _execute_task
    result = execute_callable(context=context, **execute_callable_kwargs)
             ^^^^^^^^^^^^^^^^^^^^^^^^^^^^^^^^^^^^^^^^^^^^^^^^^^^^^^^^^^^^
  File "/home/airflow/.local/lib/python3.11/site-packages/airflow/operators/python.py", line 199, in execute
    return_value = self.execute_callable()
                   ^^^^^^^^^^^^^^^^^^^^^^^
  File "/home/airflow/.local/lib/python3.11/site-packages/airflow/operators/python.py", line 216, in execute_callable
    return self.python_callable(*self.op_args, **self.op_kwargs)
           ^^^^^^^^^^^^^^^^^^^^^^^^^^^^^^^^^^^^^^^^^^^^^^^^^^^^^
  File "/opt/airflow/dags/process_scripts.py", line 25, in run_script
    raise Exception(
Exception: Échec du script /opt/***/scripts/processor_extract_country.py
STDOUT:


STDERR:
Traceback (most recent call last):
  File "/opt/***/scripts/processor_extract_country.py", line 153, in <module>
    df_result, df_debug = map_sheets_to_countries(args.input, args.output)
                          ^^^^^^^^^^^^^^^^^^^^^^^^^^^^^^^^^^^^^^^^^^^^^^^^
  File "/opt/***/scripts/processor_extract_country.py", line 92, in map_sheets_to_countries
    raise FileNotFoundError(f"Input file not found: {input_xlsx}")
FileNotFoundError: Input file not found: data/inbox/Invariants - calculs_test.xlsx

[2025-09-27T17:56:39.682+0000] {taskinstance.py:1138} INFO - Marking task as FAILED. dag_id=dynamic_process_scripts_dag, task_id=run_processor_extract_country, execution_date=20250927T175629, start_date=20250927T175635, end_date=20250927T175639
[2025-09-27T17:56:39.733+0000] {standard_task_runner.py:107} ERROR - Failed to execute job 8 for task run_processor_extract_country (Échec du script /opt/***/scripts/processor_extract_country.py
STDOUT:


STDERR:
Traceback (most recent call last):
  File "/opt/***/scripts/processor_extract_country.py", line 153, in <module>
    df_result, df_debug = map_sheets_to_countries(args.input, args.output)
                          ^^^^^^^^^^^^^^^^^^^^^^^^^^^^^^^^^^^^^^^^^^^^^^^^
  File "/opt/***/scripts/processor_extract_country.py", line 92, in map_sheets_to_countries
    raise FileNotFoundError(f"Input file not found: {input_xlsx}")
FileNotFoundError: Input file not found: data/inbox/Invariants - calculs_test.xlsx
; 254)
[2025-09-27T17:56:39.776+0000] {local_task_job_runner.py:234} INFO - Task exited with return code 1
[2025-09-27T17:56:39.840+0000] {taskinstance.py:3280} INFO - 0 downstream tasks scheduled from follow-on schedule check
